Workbook

Sheet Summary
A1: Datadog — 7-year operating trend dashboard | B1: Datadog — 7-year operating trend dashboard | C1: Datadog — 7-year operating trend dashboard | D1: Datadog — 7-year operating trend dashboard | E1: Datadog — 7-year operating trend dashboard | F1: Datadog — 7-year operating trend dashboard | G1: Datadog — 7-year operating trend dashboard | H1: Datadog — 7-year operating trend dashboard | I1: Datadog — 7-year operating trend dashboard | J1: Datadog — 7-year operating trend dashboard | K1: Datadog — 7-year operating trend dashboard | L1: Datadog — 7-year operating trend dashboard | M1: Datadog — 7-year operating trend dashboard | N1: Datadog — 7-year operating trend dashboard | O1: Datadog — 7-year operating trend dashboard | P1: Datadog — 7-year operating trend dashboard | Q1: Datadog — 7-year operating trend dashboard
A2: 2019–2025 audited GAAP actuals | Use the Income Statement tab for full detail and formulas | B2: 2019–2025 audited GAAP actuals | Use the Income Statement tab for full detail and formulas | C2: 2019–2025 audited GAAP actuals | Use the Income Statement tab for full detail and formulas | D2: 2019–2025 audited GAAP actuals | Use the Income Statement tab for full detail and formulas | E2: 2019–2025 audited GAAP actuals | Use the Income Statement tab for full detail and formulas | F2: 2019–2025 audited GAAP actuals | Use the Income Statement tab for full detail and formulas | G2: 2019–2025 audited GAAP actuals | Use the Income Statement tab for full detail and formulas | H2: 2019–2025 audited GAAP actuals | Use the Income Statement tab for full detail and formulas | I2: 2019–2025 audited GAAP actuals | Use the Income Statement tab for full detail and formulas | J2: 2019–2025 audited GAAP actuals | Use the Income Statement tab for full detail and formulas | K2: 2019–2025 audited GAAP actuals | Use the Income Statement tab for full detail and formulas | L2: 2019–2025 audited GAAP actuals | Use the Income Statement tab for full detail and formulas | M2: 2019–2025 audited GAAP actuals | Use the Income Statement tab for full detail and formulas | N2: 2019–2025 audited GAAP actuals | Use the Income Statement tab for full detail and formulas | O2: 2019–2025 audited GAAP actuals | Use the Income Statement tab for full detail and formulas | P2: 2019–2025 audited GAAP actuals | Use the Income Statement tab for full detail and formulas | Q2: 2019–2025 audited GAAP actuals | Use the Income Statement tab for full detail and formulas
A4: Revenue CAGR | B4: Revenue CAGR | D4: 2025 gross margin | E4: 2025 gross margin | G4: 2025 operating margin | H4: 2025 operating margin | J4: 2025 net margin | K4: 2025 net margin | M4: 2025 diluted EPS | N4: 2025 diluted EPS | P4: Y/E share CAGR | Q4: Y/E share CAGR
A5: =('Income Statement'!H8/'Income Statement'!B8)^(1/6)-1 -> 0.45394663 | D5: ='Income Statement'!H13 -> 0.79955491 | G5: ='Income Statement'!H25 -> -0.012947463 | J5: ='Income Statement'!H36 -> 0.031437418 | M5: ='Income Statement'!H39 -> 0.31 | P5: =('Income Statement'!H44/'Income Statement'!B44)^(1/6)-1 -> 0.029331681
A45: Reading note: diluted EPS growth is intentionally blank when the prior or current EPS is non-positive; percentages across zero are not economically meaningful. | B45: Reading note: diluted EPS growth is intentionally blank when the prior or current EPS is non-positive; percentages across zero are not economically meaningful. | C45: Reading note: diluted EPS growth is intentionally blank when the prior or current EPS is non-positive; percentages across zero are not economically meaningful. | D45: Reading note: diluted EPS growth is intentionally blank when the prior or current EPS is non-positive; percentages across zero are not economically meaningful. | E45: Reading note: diluted EPS growth is intentionally blank when the prior or current EPS is non-positive; percentages across zero are not economically meaningful. | F45: Reading note: diluted EPS growth is intentionally blank when the prior or current EPS is non-positive; percentages across zero are not economically meaningful. | G45: Reading note: diluted EPS growth is intentionally blank when the prior or current EPS is non-positive; percentages across zero are not economically meaningful. | H45: Reading note: diluted EPS growth is intentionally blank when the prior or current EPS is non-positive; percentages across zero are not economically meaningful. | I45: Reading note: diluted EPS growth is intentionally blank when the prior or current EPS is non-positive; percentages across zero are not economically meaningful. | J45: Reading note: diluted EPS growth is intentionally blank when the prior or current EPS is non-positive; percentages across zero are not economically meaningful. | K45: Reading note: diluted EPS growth is intentionally blank when the prior or current EPS is non-positive; percentages across zero are not economically meaningful. | L45: Reading note: diluted EPS growth is intentionally blank when the prior or current EPS is non-positive; percentages across zero are not economically meaningful. | M45: Reading note: diluted EPS growth is intentionally blank when the prior or current EPS is non-positive; percentages across zero are not economically meaningful. | N45: Reading note: diluted EPS growth is intentionally blank when the prior or current EPS is non-positive; percentages across zero are not economically meaningful. | O45: Reading note: diluted EPS growth is intentionally blank when the prior or current EPS is non-positive; percentages across zero are not economically meaningful. | P45: Reading note: diluted EPS growth is intentionally blank when the prior or current EPS is non-positive; percentages across zero are not economically meaningful. | Q45: Reading note: diluted EPS growth is intentionally blank when the prior or current EPS is non-positive; percentages across zero are not economically meaningful.

Sheet Income Statement
A1: Datadog (NASDAQ: DDOG) — 7-year income statement | B1: Datadog (NASDAQ: DDOG) — 7-year income statement | C1: Datadog (NASDAQ: DDOG) — 7-year income statement | D1: Datadog (NASDAQ: DDOG) — 7-year income statement | E1: Datadog (NASDAQ: DDOG) — 7-year income statement | F1: Datadog (NASDAQ: DDOG) — 7-year income statement | G1: Datadog (NASDAQ: DDOG) — 7-year income statement | H1: Datadog (NASDAQ: DDOG) — 7-year income statement
A2: GAAP actuals | Fiscal years ended December 31 | USD millions, except per-share data | B2: GAAP actuals | Fiscal years ended December 31 | USD millions, except per-share data | C2: GAAP actuals | Fiscal years ended December 31 | USD millions, except per-share data | D2: GAAP actuals | Fiscal years ended December 31 | USD millions, except per-share data | E2: GAAP actuals | Fiscal years ended December 31 | USD millions, except per-share data | F2: GAAP actuals | Fiscal years ended December 31 | USD millions, except per-share data | G2: GAAP actuals | Fiscal years ended December 31 | USD millions, except per-share data | H2: GAAP actuals | Fiscal years ended December 31 | USD millions, except per-share data
A3: Legend: green font = linked reported data from Source Data; black font = workbook calculation | B3: Legend: green font = linked reported data from Source Data; black font = workbook calculation | C3: Legend: green font = linked reported data from Source Data; black font = workbook calculation | D3: Legend: green font = linked reported data from Source Data; black font = workbook calculation | E3: Legend: green font = linked reported data from Source Data; black font = workbook calculation | F3: Legend: green font = linked reported data from Source Data; black font = workbook calculation | G3: Legend: green font = linked reported data from Source Data; black font = workbook calculation | H3: Legend: green font = linked reported data from Source Data; black font = workbook calculation
A5: Fiscal year | B5: 2019 | C5: 2020 | D5: 2021 | E5: 2022 | F5: 2023 | G5: 2024 | H5: 2025
A7: 1–3 Revenue, cost of revenue & gross profit | B7: 1–3 Revenue, cost of revenue & gross profit | C7: 1–3 Revenue, cost of revenue & gross profit | D7: 1–3 Revenue, cost of revenue & gross profit | E7: 1–3 Revenue, cost of revenue & gross profit | F7: 1–3 Revenue, cost of revenue & gross profit | G7: 1–3 Revenue, cost of revenue & gross profit | H7: 1–3 Revenue, cost of revenue & gross profit
A8: Revenue | B8: ='Source Data'!B5 -> 362.78 | C8: ='Source Data'!C5 -> 603.466 | D8: ='Source Data'!D5 -> 1028.784 | E8: ='Source Data'!E5 -> 1675.1 | F8: ='Source Data'!F5 -> 2128.359 | G8: ='Source Data'!G5 -> 2684.275 | H8: ='Source Data'!H5 -> 3427.158
A9: YoY growth | B9: ="" | C9: =IF(B8=0,"",C8/B8-1) -> 0.66344892 | D9: =IF(C8=0,"",D8/C8-1) -> 0.70479198 | E9: =IF(D8=0,"",E8/D8-1) -> 0.62823294 | F9: =IF(E8=0,"",F8/E8-1) -> 0.27058623 | G9: =IF(F8=0,"",G8/F8-1) -> 0.26119466 | H9: =IF(G8=0,"",H8/G8-1) -> 0.27675369
A10: Cost of revenue | B10: ='Source Data'!B6 -> 88.949 | C10: ='Source Data'!C6 -> 130.197 | D10: ='Source Data'!D6 -> 234.245 | E10: ='Source Data'!E6 -> 346.743 | F10: ='Source Data'!F6 -> 409.908 | G10: ='Source Data'!G6 -> 515.531 | H10: ='Source Data'!H6 -> 686.957
A11: Cost of revenue as % of revenue | B11: =B10/B8 -> 0.24518717 | C11: =C10/C8 -> 0.21574869 | D11: =D10/D8 -> 0.22769114 | E11: =E10/E8 -> 0.20699839 | F11: =F10/F8 -> 0.19259345 | G11: =G10/G8 -> 0.19205596 | H11: =H10/H8 -> 0.20044509
A12: Gross profit | B12: =B8-B10 -> 273.831 | C12: =C8-C10 -> 473.269 | D12: =D8-D10 -> 794.539 | E12: =E8-E10 -> 1328.357 | F12: =F8-F10 -> 1718.451 | G12: =G8-G10 -> 2168.744 | H12: =H8-H10 -> 2740.201
A13: Gross margin | B13: =B12/B8 -> 0.75481283 | C13: =C12/C8 -> 0.78425131 | D13: =D12/D8 -> 0.77230886 | E13: =E12/E8 -> 0.79300161 | F13: =F12/F8 -> 0.80740655 | G13: =G12/G8 -> 0.80794404 | H13: =H12/H8 -> 0.79955491
A15: 4–5 Operating expenses & operating income | B15: 4–5 Operating expenses & operating income | C15: 4–5 Operating expenses & operating income | D15: 4–5 Operating expenses & operating income | E15: 4–5 Operating expenses & operating income | F15: 4–5 Operating expenses & operating income | G15: 4–5 Operating expenses & operating income | H15: 4–5 Operating expenses & operating income
A16: Research and development | B16: ='Source Data'!B8 -> 111.425 | C16: ='Source Data'!C8 -> 210.626 | D16: ='Source Data'!D8 -> 419.769 | E16: ='Source Data'!E8 -> 752.351 | F16: ='Source Data'!F8 -> 962.447 | G16: ='Source Data'!G8 -> 1152.703 | H16: ='Source Data'!H8 -> 1548.451
A17: Sales and marketing | B17: ='Source Data'!B9 -> 146.657 | C17: ='Source Data'!C9 -> 213.66 | D17: ='Source Data'!D9 -> 299.497 | E17: ='Source Data'!E9 -> 495.288 | F17: ='Source Data'!F9 -> 609.276 | G17: ='Source Data'!G9 -> 756.605 | H17: ='Source Data'!H9 -> 956.423
A18: General and administrative | B18: ='Source Data'!B10 -> 35.889 | C18: ='Source Data'!C10 -> 62.756 | D18: ='Source Data'!D10 -> 94.429 | E18: ='Source Data'!E10 -> 139.413 | F18: ='Source Data'!F10 -> 180.192 | G18: ='Source Data'!G10 -> 205.152 | H18: ='Source Data'!H10 -> 279.7
A19: Total operating expenses | B19: =SUM(B16:B18) -> 293.971 | C19: =SUM(C16:C18) -> 487.042 | D19: =SUM(D16:D18) -> 813.695 | E19: =SUM(E16:E18) -> 1387.052 | F19: =SUM(F16:F18) -> 1751.915 | G19: =SUM(G16:G18) -> 2114.46 | H19: =SUM(H16:H18) -> 2784.574
A20: R&D as % of revenue | B20: =B16/B8 -> 0.30714207 | C20: =C16/C8 -> 0.34902712 | D20: =D16/D8 -> 0.40802442 | E20: =E16/E8 -> 0.44913796 | F20: =F16/F8 -> 0.45220144 | G20: =G16/G8 -> 0.42942806 | H20: =H16/H8 -> 0.4518178
A21: Sales & marketing as % of revenue | B21: =B17/B8 -> 0.40425878 | C21: =C17/C8 -> 0.35405474 | D21: =D17/D8 -> 0.29111747 | E21: =E17/E8 -> 0.29567668 | F21: =F17/F8 -> 0.28626562 | G21: =G17/G8 -> 0.28186568 | H21: =H17/H8 -> 0.27907176
A22: G&A as % of revenue | B22: =B18/B8 -> 0.098927725 | C22: =C18/C8 -> 0.1039926 | D22: =D18/D8 -> 0.091787003 | E22: =E18/E8 -> 0.083226673 | F22: =F18/F8 -> 0.084662409 | G22: =G18/G8 -> 0.076427341 | H22: =H18/H8 -> 0.081612812
A23: Operating expenses as % of revenue | B23: =B19/B8 -> 0.81032857 | C23: =C19/C8 -> 0.80707447 | D23: =D19/D8 -> 0.7909289 | E23: =E19/E8 -> 0.82804131 | F23: =F19/F8 -> 0.82312946 | G23: =G19/G8 -> 0.78772108 | H23: =H19/H8 -> 0.81250237
A24: Operating income (loss) | B24: =B12-B19 -> -20.14 | C24: =C12-C19 -> -13.773 | D24: =D12-D19 -> -19.156 | E24: =E12-E19 -> -58.695 | F24: =F12-F19 -> -33.464 | G24: =G12-G19 -> 54.284 | H24: =H12-H19 -> -44.373
A25: Operating margin | B25: =B24/B8 -> -0.05551574 | C25: =C24/C8 -> -0.022823158 | D25: =D24/D8 -> -0.018620041 | E25: =E24/E8 -> -0.035039699 | F25: =F24/F8 -> -0.015722911 | G25: =G24/G8 -> 0.020222965 | H25: =H24/H8 -> -0.012947463
A27: 6–7 Below-the-line, net income, EPS & shares | B27: 6–7 Below-the-line, net income, EPS & shares | C27: 6–7 Below-the-line, net income, EPS & shares | D27: 6–7 Below-the-line, net income, EPS & shares | E27: 6–7 Below-the-line, net income, EPS & shares | F27: 6–7 Below-the-line, net income, EPS & shares | G27: 6–7 Below-the-line, net income, EPS & shares | H27: 6–7 Below-the-line, net income, EPS & shares
A28: Interest expense | B28: ='Source Data'!B13 -> -0.032 | C28: ='Source Data'!C13 -> -30.434 | D28: ='Source Data'!D13 -> -21.052 | E28: ='Source Data'!E13 -> -16.535 | F28: ='Source Data'!F13 -> -6.302 | G28: ='Source Data'!G13 -> -7.068 | H28: ='Source Data'!H13 -> -11.059
A29: Interest income and other income, net | B29: ='Source Data'!B14 -> 4.196 | C29: ='Source Data'!C14 -> 21.985 | D29: ='Source Data'!D14 -> 21.786 | E29: ='Source Data'!E14 -> 37.16 | F29: ='Source Data'!F14 -> 100.001 | G29: ='Source Data'!G14 -> 156.724 | H29: ='Source Data'!H14 -> 182.453
A30: Other income (loss), net | B30: =SUM(B28:B29) -> 4.164 | C30: =SUM(C28:C29) -> -8.449 | D30: =SUM(D28:D29) -> 0.734 | E30: =SUM(E28:E29) -> 20.625 | F30: =SUM(F28:F29) -> 93.699 | G30: =SUM(G28:G29) -> 149.656 | H30: =SUM(H28:H29) -> 171.394
A31: Income (loss) before income taxes | B31: =B24+B30 -> -15.976 | C31: =C24+C30 -> -22.222 | D31: =D24+D30 -> -18.422 | E31: =E24+E30 -> -38.07 | F31: =F24+F30 -> 60.235 | G31: =G24+G30 -> 203.94 | H31: =H24+H30 -> 127.021
A32: Pre-tax margin | B32: =B31/B8 -> -0.044037709 | C32: =C31/C8 -> -0.036823947 | D32: =D31/D8 -> -0.017906577 | E32: =E31/E8 -> -0.022727001 | F32: =F31/F8 -> 0.028301147 | G32: =G31/G8 -> 0.075975822 | H32: =H31/H8 -> 0.037063071
A33: Provision for income taxes | B33: ='Source Data'!B17 -> 0.734 | C33: ='Source Data'!C17 -> 2.325 | D33: ='Source Data'!D17 -> 2.323 | E33: ='Source Data'!E17 -> 12.09 | F33: ='Source Data'!F17 -> 11.667 | G33: ='Source Data'!G17 -> 20.194 | H33: ='Source Data'!H17 -> 19.28
A34: Effective tax rate (only when pre-tax income > 0) | B34: =IF(B31>0,B33/B31,"") | C34: =IF(C31>0,C33/C31,"") | D34: =IF(D31>0,D33/D31,"") | E34: =IF(E31>0,E33/E31,"") | F34: =IF(F31>0,F33/F31,"") -> 0.19369138 | G34: =IF(G31>0,G33/G31,"") -> 0.099019319 | H34: =IF(H31>0,H33/H31,"") -> 0.15178593
A35: Net income (loss) | B35: =B31-B33 -> -16.71 | C35: =C31-C33 -> -24.547 | D35: =D31-D33 -> -20.745 | E35: =E31-E33 -> -50.16 | F35: =F31-F33 -> 48.568 | G35: =G31-G33 -> 183.746 | H35: =H31-H33 -> 107.741
A36: Net margin | B36: =B35/B8 -> -0.046060974 | C36: =C35/C8 -> -0.040676691 | D36: =D35/D8 -> -0.020164583 | E36: =E35/E8 -> -0.029944481 | F36: =F35/F8 -> 0.022819459 | G36: =G35/G8 -> 0.068452748 | H36: =H35/H8 -> 0.031437418
A38: Basic EPS | B38: ='Source Data'!B19 -> -0.12 | C38: ='Source Data'!C19 -> -0.08 | D38: ='Source Data'!D19 -> -0.07 | E38: ='Source Data'!E19 -> -0.16 | F38: ='Source Data'!F19 -> 0.15 | G38: ='Source Data'!G19 -> 0.55 | H38: ='Source Data'!H19 -> 0.31
A39: Diluted EPS | B39: ='Source Data'!B20 -> -0.12 | C39: ='Source Data'!C20 -> -0.08 | D39: ='Source Data'!D20 -> -0.07 | E39: ='Source Data'!E20 -> -0.16 | F39: ='Source Data'!F20 -> 0.14 | G39: ='Source Data'!G20 -> 0.52 | H39: ='Source Data'!H20 -> 0.31
A40: Diluted EPS YoY growth (positive base only) | B40: ="" | C40: =IF(OR(B39<=0,C39<=0),"",C39/B39-1) | D40: =IF(OR(C39<=0,D39<=0),"",D39/C39-1) | E40: =IF(OR(D39<=0,E39<=0),"",E39/D39-1) | F40: =IF(OR(E39<=0,F39<=0),"",F39/E39-1) | G40: =IF(OR(F39<=0,G39<=0),"",G39/F39-1) -> 2.7142857 | H40: =IF(OR(G39<=0,H39<=0),"",H39/G39-1) -> -0.40384615
A41: Weighted average shares — basic | B41: ='Source Data'!B21 -> 139.873 | C41: ='Source Data'!C21 -> 300.35 | D41: ='Source Data'!D21 -> 309.048 | E41: ='Source Data'!E21 -> 315.41 | F41: ='Source Data'!F21 -> 324.033 | G41: ='Source Data'!G21 -> 336.172 | H41: ='Source Data'!H21 -> 347.309
A42: Weighted average shares — diluted | B42: ='Source Data'!B22 -> 139.873 | C42: ='Source Data'!C22 -> 300.35 | D42: ='Source Data'!D22 -> 309.048 | E42: ='Source Data'!E22 -> 315.41 | F42: ='Source Data'!F22 -> 350.292 | G42: ='Source Data'!G22 -> 358.636 | H42: ='Source Data'!H22 -> 363.472
A43: Potential dilution vs basic share count | B43: =B42/B41-1 -> 0 | C43: =C42/C41-1 -> 0 | D43: =D42/D41-1 -> 0 | E43: =E42/E41-1 -> 0 | F43: =F42/F41-1 -> 0.081038042 | G43: =G42/G41-1 -> 0.066822936 | H43: =H42/H41-1 -> 0.046537809
A44: Year-end shares outstanding | B44: ='Source Data'!B23 -> 296.38695 | C44: ='Source Data'!C23 -> 305.88006 | D44: ='Source Data'!D23 -> 313.36544 | E44: ='Source Data'!E23 -> 319.18984 | F44: ='Source Data'!F23 -> 331.07975 | G44: ='Source Data'!G23 -> 342.11878 | H44: ='Source Data'!H23 -> 352.52597
A45: Year-end shares YoY growth | B45: ="" | C45: =IF(B44=0,"",C44/B44-1) -> 0.032029457 | D45: =IF(C44=0,"",D44/C44-1) -> 0.024471598 | E45: =IF(D44=0,"",E44/D44-1) -> 0.018586625 | F45: =IF(E44=0,"",F44/E44-1) -> 0.037250255 | G45: =IF(F44=0,"",G44/F44-1) -> 0.033342529 | H45: =IF(G44=0,"",H44/G44-1) -> 0.030419812

Sheet Source Data
A1: Datadog — source-reported GAAP financials | B1: Datadog — source-reported GAAP financials | C1: Datadog — source-reported GAAP financials | D1: Datadog — source-reported GAAP financials | E1: Datadog — source-reported GAAP financials | F1: Datadog — source-reported GAAP financials | G1: Datadog — source-reported GAAP financials | H1: Datadog — source-reported GAAP financials | I1: Datadog — source-reported GAAP financials | J1: Datadog — source-reported GAAP financials
A2: Audited annual figures normalized from $000 to USD millions. Source values are hardcoded; calculated rows live on the Income Statement tab. | B2: Audited annual figures normalized from $000 to USD millions. Source values are hardcoded; calculated rows live on the Income Statement tab. | C2: Audited annual figures normalized from $000 to USD millions. Source values are hardcoded; calculated rows live on the Income Statement tab. | D2: Audited annual figures normalized from $000 to USD millions. Source values are hardcoded; calculated rows live on the Income Statement tab. | E2: Audited annual figures normalized from $000 to USD millions. Source values are hardcoded; calculated rows live on the Income Statement tab. | F2: Audited annual figures normalized from $000 to USD millions. Source values are hardcoded; calculated rows live on the Income Statement tab. | G2: Audited annual figures normalized from $000 to USD millions. Source values are hardcoded; calculated rows live on the Income Statement tab. | H2: Audited annual figures normalized from $000 to USD millions. Source values are hardcoded; calculated rows live on the Income Statement tab. | I2: Audited annual figures normalized from $000 to USD millions. Source values are hardcoded; calculated rows live on the Income Statement tab. | J2: Audited annual figures normalized from $000 to USD millions. Source values are hardcoded; calculated rows live on the Income Statement tab.
A3: Metric | B3: 2019 | C3: 2020 | D3: 2021 | E3: 2022 | F3: 2023 | G3: 2024 | H3: 2025 | I3: Units | J3: Normalization / comparability note
A5: Revenue | B5: 362.78 | C5: 603.466 | D5: 1028.784 | E5: 1675.1 | F5: 2128.359 | G5: 2684.275 | H5: 3427.158 | I5: $mm | J5: Comparable as reported; presentation normalized to consistent units.
A6: Cost of revenue | B6: 88.949 | C6: 130.197 | D6: 234.245 | E6: 346.743 | F6: 409.908 | G6: 515.531 | H6: 686.957 | I6: $mm | J6: Comparable as reported; presentation normalized to consistent units.
A7: Gross profit — reported | B7: 273.831 | C7: 473.269 | D7: 794.539 | E7: 1328.357 | F7: 1718.451 | G7: 2168.744 | H7: 2740.201 | I7: $mm | J7: Comparable as reported; presentation normalized to consistent units.
A8: Research and development | B8: 111.425 | C8: 210.626 | D8: 419.769 | E8: 752.351 | F8: 962.447 | G8: 1152.703 | H8: 1548.451 | I8: $mm | J8: Comparable as reported; presentation normalized to consistent units.
A9: Sales and marketing | B9: 146.657 | C9: 213.66 | D9: 299.497 | E9: 495.288 | F9: 609.276 | G9: 756.605 | H9: 956.423 | I9: $mm | J9: Comparable as reported; presentation normalized to consistent units.
A10: General and administrative | B10: 35.889 | C10: 62.756 | D10: 94.429 | E10: 139.413 | F10: 180.192 | G10: 205.152 | H10: 279.7 | I10: $mm | J10: Comparable as reported; presentation normalized to consistent units.
A11: Total operating expenses — reported | B11: 293.971 | C11: 487.042 | D11: 813.695 | E11: 1387.052 | F11: 1751.915 | G11: 2114.46 | H11: 2784.574 | I11: $mm | J11: Comparable as reported; presentation normalized to consistent units.
A12: Operating income (loss) — reported | B12: -20.14 | C12: -13.773 | D12: -19.156 | E12: -58.695 | F12: -33.464 | G12: 54.284 | H12: -44.373 | I12: $mm | J12: Comparable as reported; presentation normalized to consistent units.
A13: Interest expense | B13: -0.032 | C13: -30.434 | D13: -21.052 | E13: -16.535 | F13: -6.302 | G13: -7.068 | H13: -11.059 | I13: $mm | J13: Comparable as reported; presentation normalized to consistent units.
A14: Interest income and other income, net | B14: 4.196 | C14: 21.985 | D14: 21.786 | E14: 37.16 | F14: 100.001 | G14: 156.724 | H14: 182.453 | I14: $mm | J14: Comparable as reported; presentation normalized to consistent units.
A15: Other income (loss), net — reported | B15: 4.164 | C15: -8.449 | D15: 0.734 | E15: 20.625 | F15: 93.699 | G15: 149.656 | H15: 171.394 | I15: $mm | J15: Comparable as reported; presentation normalized to consistent units.
... A23: Year-end shares outstanding | B23: 296.38695 | C23: 305.88006 | D23: 313.36544 | E23: 319.18984 | F23: 331.07975 | G23: 342.11878 | H23: 352.52597 | I23: mm shares | J23: Comparable as reported; presentation normalized to consistent units.

Sheet Sources & Checks
A1: Sources, normalization notes & validation checks | B1: Sources, normalization notes & validation checks | C1: Sources, normalization notes & validation checks | D1: Sources, normalization notes & validation checks | E1: Sources, normalization notes & validation checks | F1: Sources, normalization notes & validation checks | G1: Sources, normalization notes & validation checks | H1: Sources, normalization notes & validation checks | I1: Sources, normalization notes & validation checks | J1: Sources, normalization notes & validation checks
A3: Source ID | B3: Periods | C3: Source | D3: Filing date | E3: Statement location | F3: URL | J3: Overall status
A4: SRC-001 | B4: FY2019 | C4: Datadog FY2021 Form 10-K | D4: 44617 | E4: Consolidated Statements of Operations p.58; share disclosures p.57–60 | F4: https://www.sec.gov/Archives/edgar/data/1561550/000156155022000009/ddog-20211231.htm | J4: =IF(COUNTIF(H15:H56,"REVIEW")=0,"OK","REVIEW") -> OK
A5: SRC-002 | B5: FY2020–FY2022 | C5: Datadog FY2022 Form 10-K | D5: 44981 | E5: Consolidated Statements of Operations p.58; share disclosures p.57–60 | F5: https://www.sec.gov/Archives/edgar/data/1561550/000156155023000006/ddog-20221231.htm
A6: SRC-003 | B6: FY2023–FY2025 | C6: Datadog FY2025 Form 10-K | D6: 46071 | E6: Consolidated Statements of Operations p.63; share disclosures p.62–65 | F6: https://www.sec.gov/Archives/edgar/data/1561550/000162828026008819/ddog-20251231.htm
A8: Normalization notes | B8: Normalization notes | C8: Normalization notes | D8: Normalization notes | E8: Normalization notes | F8: Normalization notes | G8: Normalization notes | H8: Normalization notes
A9: Topic | B9: Treatment | C9: Rationale
A10: Units | B10: All statement values converted from $000 to $mm; EPS remains $/share; share counts are in millions. | C10: Makes the 7-year schedule readable and formula-friendly.
A11: Tax line | B11: Provision for income taxes is stored as a positive expense and subtracted from pre-tax income. | C11: The 2019–2022 source statements display the expense in parentheses during loss years.
A13: Validation checks | B13: Validation checks | C13: Validation checks | D13: Validation checks | E13: Validation checks | F13: Validation checks | G13: Validation checks | H13: Validation checks
A14: Check ID | B14: FY | C14: Test | D14: Expected | E14: Observed | F14: Variance | G14: Tolerance | H14: Status
A15: CHK-001 | B15: 2019 | C15: Gross profit = revenue − cost of revenue | D15: ='Source Data'!B7 -> 273.831 | E15: ='Income Statement'!B12 -> 273.831 | F15: =ROUND(E15-D15,6) -> 0 | G15: 0.001 | H15: =IF(ABS(F15)<=G15,"OK","REVIEW") -> OK
A16: CHK-002 | B16: 2020 | C16: Gross profit = revenue − cost of revenue | D16: ='Source Data'!C7 -> 473.269 | E16: ='Income Statement'!C12 -> 473.269 | F16: =ROUND(E16-D16,6) -> 0 | G16: 0.001 | H16: =IF(ABS(F16)<=G16,"OK","REVIEW") -> OK
A17: CHK-003 | B17: 2021 | C17: Gross profit = revenue − cost of revenue | D17: ='Source Data'!D7 -> 794.539 | E17: ='Income Statement'!D12 -> 794.539 | F17: =ROUND(E17-D17,6) -> 0 | G17: 0.001 | H17: =IF(ABS(F17)<=G17,"OK","REVIEW") -> OK
A18: CHK-004 | B18: 2022 | C18: Gross profit = revenue − cost of revenue | D18: ='Source Data'!E7 -> 1328.357 | E18: ='Income Statement'!E12 -> 1328.357 | F18: =ROUND(E18-D18,6) -> 0 | G18: 0.001 | H18: =IF(ABS(F18)<=G18,"OK","REVIEW") -> OK
A19: CHK-005 | B19: 2023 | C19: Gross profit = revenue − cost of revenue | D19: ='Source Data'!F7 -> 1718.451 | E19: ='Income Statement'!F12 -> 1718.451 | F19: =ROUND(E19-D19,6) -> 0 | G19: 0.001 | H19: =IF(ABS(F19)<=G19,"OK","REVIEW") -> OK
A20: CHK-006 | B20: 2024 | C20: Gross profit = revenue − cost of revenue | D20: ='Source Data'!G7 -> 2168.744 | E20: ='Income Statement'!G12 -> 2168.744 | F20: =ROUND(E20-D20,6) -> 0 | G20: 0.001 | H20: =IF(ABS(F20)<=G20,"OK","REVIEW") -> OK
A21: CHK-007 | B21: 2025 | C21: Gross profit = revenue − cost of revenue | D21: ='Source Data'!H7 -> 2740.201 | E21: ='Income Statement'!H12 -> 2740.201 | F21: =ROUND(E21-D21,6) -> 0 | G21: 0.001 | H21: =IF(ABS(F21)<=G21,"OK","REVIEW") -> OK
A22: CHK-008 | B22: 2019 | C22: Operating expenses = R&D + S&M + G&A | D22: ='Source Data'!B11 -> 293.971 | E22: ='Income Statement'!B19 -> 293.971 | F22: =ROUND(E22-D22,6) -> 0 | G22: 0.001 | H22: =IF(ABS(F22)<=G22,"OK","REVIEW") -> OK
A23: CHK-009 | B23: 2020 | C23: Operating expenses = R&D + S&M + G&A | D23: ='Source Data'!C11 -> 487.042 | E23: ='Income Statement'!C19 -> 487.042 | F23: =ROUND(E23-D23,6) -> 0 | G23: 0.001 | H23: =IF(ABS(F23)<=G23,"OK","REVIEW") -> OK
A24: CHK-010 | B24: 2021 | C24: Operating expenses = R&D + S&M + G&A | D24: ='Source Data'!D11 -> 813.695 | E24: ='Income Statement'!D19 -> 813.695 | F24: =ROUND(E24-D24,6) -> 0 | G24: 0.001 | H24: =IF(ABS(F24)<=G24,"OK","REVIEW") -> OK
A25: CHK-011 | B25: 2022 | C25: Operating expenses = R&D + S&M + G&A | D25: ='Source Data'!E11 -> 1387.052 | E25: ='Income Statement'!E19 -> 1387.052 | F25: =ROUND(E25-D25,6) -> 0 | G25: 0.001 | H25: =IF(ABS(F25)<=G25,"OK","REVIEW") -> OK
A26: CHK-012 | B26: 2023 | C26: Operating expenses = R&D + S&M + G&A | D26: ='Source Data'!F11 -> 1751.915 | E26: ='Income Statement'!F19 -> 1751.915 | F26: =ROUND(E26-D26,6) -> 0 | G26: 0.001 | H26: =IF(ABS(F26)<=G26,"OK","REVIEW") -> OK
A27: CHK-013 | B27: 2024 | C27: Operating expenses = R&D + S&M + G&A | D27: ='Source Data'!G11 -> 2114.46 | E27: ='Income Statement'!G19 -> 2114.46 | F27: =ROUND(E27-D27,6) -> 0 | G27: 0.001 | H27: =IF(ABS(F27)<=G27,"OK","REVIEW") -> OK
A28: CHK-014 | B28: 2025 | C28: Operating expenses = R&D + S&M + G&A | D28: ='Source Data'!H11 -> 2784.574 | E28: ='Income Statement'!H19 -> 2784.574 | F28: =ROUND(E28-D28,6) -> 0 | G28: 0.001 | H28: =IF(ABS(F28)<=G28,"OK","REVIEW") -> OK
A29: CHK-015 | B29: 2019 | C29: Operating income = gross profit − operating expenses | D29: ='Source Data'!B12 -> -20.14 | E29: ='Income Statement'!B24 -> -20.14 | F29: =ROUND(E29-D29,6) -> 0 | G29: 0.001 | H29: =IF(ABS(F29)<=G29,"OK","REVIEW") -> OK
A30: CHK-016 | B30: 2020 | C30: Operating income = gross profit − operating expenses | D30: ='Source Data'!C12 -> -13.773 | E30: ='Income Statement'!C24 -> -13.773 | F30: =ROUND(E30-D30,6) -> 0 | G30: 0.001 | H30: =IF(ABS(F30)<=G30,"OK","REVIEW") -> OK
A31: CHK-017 | B31: 2021 | C31: Operating income = gross profit − operating expenses | D31: ='Source Data'!D12 -> -19.156 | E31: ='Income Statement'!D24 -> -19.156 | F31: =ROUND(E31-D31,6) -> 0 | G31: 0.001 | H31: =IF(ABS(F31)<=G31,"OK","REVIEW") -> OK
A32: CHK-018 | B32: 2022 | C32: Operating income = gross profit − operating expenses | D32: ='Source Data'!E12 -> -58.695 | E32: ='Income Statement'!E24 -> -58.695 | F32: =ROUND(E32-D32,6) -> 0 | G32: 0.001 | H32: =IF(ABS(F32)<=G32,"OK","REVIEW") -> OK
A33: CHK-019 | B33: 2023 | C33: Operating income = gross profit − operating expenses | D33: ='Source Data'!F12 -> -33.464 | E33: ='Income Statement'!F24 -> -33.464 | F33: =ROUND(E33-D33,6) -> 0 | G33: 0.001 | H33: =IF(ABS(F33)<=G33,"OK","REVIEW") -> OK
A34: CHK-020 | B34: 2024 | C34: Operating income = gross profit − operating expenses | D34: ='Source Data'!G12 -> 54.284 | E34: ='Income Statement'!G24 -> 54.284 | F34: =ROUND(E34-D34,6) -> 0 | G34: 0.001 | H34: =IF(ABS(F34)<=G34,"OK","REVIEW") -> OK
A35: CHK-021 | B35: 2025 | C35: Operating income = gross profit − operating expenses | D35: ='Source Data'!H12 -> -44.373 | E35: ='Income Statement'!H24 -> -44.373 | F35: =ROUND(E35-D35,6) -> 0 | G35: 0.001 | H35: =IF(ABS(F35)<=G35,"OK","REVIEW") -> OK
A36: CHK-022 | B36: 2019 | C36: Other income, net = interest expense + interest/other income | D36: ='Source Data'!B15 -> 4.164 | E36: ='Income Statement'!B30 -> 4.164 | F36: =ROUND(E36-D36,6) -> 0 | G36: 0.001 | H36: =IF(ABS(F36)<=G36,"OK","REVIEW") -> OK
A37: CHK-023 | B37: 2020 | C37: Other income, net = interest expense + interest/other income | D37: ='Source Data'!C15 -> -8.449 | E37: ='Income Statement'!C30 -> -8.449 | F37: =ROUND(E37-D37,6) -> 0 | G37: 0.001 | H37: =IF(ABS(F37)<=G37,"OK","REVIEW") -> OK
A38: CHK-024 | B38: 2021 | C38: Other income, net = interest expense + interest/other income | D38: ='Source Data'!D15 -> 0.734 | E38: ='Income Statement'!D30 -> 0.734 | F38: =ROUND(E38-D38,6) -> 0 | G38: 0.001 | H38: =IF(ABS(F38)<=G38,"OK","REVIEW") -> OK
A39: CHK-025 | B39: 2022 | C39: Other income, net = interest expense + interest/other income | D39: ='Source Data'!E15 -> 20.625 | E39: ='Income Statement'!E30 -> 20.625 | F39: =ROUND(E39-D39,6) -> 0 | G39: 0.001 | H39: =IF(ABS(F39)<=G39,"OK","REVIEW") -> OK
A40: CHK-026 | B40: 2023 | C40: Other income, net = interest expense + interest/other income | D40: ='Source Data'!F15 -> 93.699 | E40: ='Income Statement'!F30 -> 93.699 | F40: =ROUND(E40-D40,6) -> 0 | G40: 0.001 | H40: =IF(ABS(F40)<=G40,"OK","REVIEW") -> OK
A41: CHK-027 | B41: 2024 | C41: Other income, net = interest expense + interest/other income | D41: ='Source Data'!G15 -> 149.656 | E41: ='Income Statement'!G30 -> 149.656 | F41: =ROUND(E41-D41,6) -> 0 | G41: 0.001 | H41: =IF(ABS(F41)<=G41,"OK","REVIEW") -> OK
A42: CHK-028 | B42: 2025 | C42: Other income, net = interest expense + interest/other income | D42: ='Source Data'!H15 -> 171.394 | E42: ='Income Statement'!H30 -> 171.394 | F42: =ROUND(E42-D42,6) -> 0 | G42: 0.001 | H42: =IF(ABS(F42)<=G42,"OK","REVIEW") -> OK
A43: CHK-029 | B43: 2019 | C43: Pre-tax income = operating income + other income, net | D43: ='Source Data'!B16 -> -15.976 | E43: ='Income Statement'!B31 -> -15.976 | F43: =ROUND(E43-D43,6) -> 0 | G43: 0.001 | H43: =IF(ABS(F43)<=G43,"OK","REVIEW") -> OK
...
